<mujoco model="reacher">
	<compiler angle="radian" inertiafromgeom="true"/>
	<default>
		<joint armature="1" damping="1" limited="true" frictionloss=0.1/>
		<geom contype="1" friction="1 0.1 0.1" rgba="0.7 0.7 0 1"/>
	</default>
	<option gravity="0 0 -9.81" integrator="RK4" timestep="0.01"/>
	<worldbody>
		<!-- Arena -->
		<geom conaffinity="0" contype="0" name="ground" pos="0 0 0" rgba="0.9 0.9 0.9 1" size="1 1 10" type="plane"/>
		<geom conaffinity="1" contype="1" fromto="-.3 -.3 .01 .3 -.3 .01" name="sideS" rgba="0.9 0.4 0.6 1" size=".02" type="capsule"/>
		<geom conaffinity="1" contype="1" fromto=" .3 -.3 .01 .3  .3 .01" name="sideE" rgba="0.9 0.4 0.6 1" size=".02" type="capsule"/>
		<geom conaffinity="1" contype="1" fromto="-.3  .3 .01 .3  .3 .01" name="sideN" rgba="0.9 0.4 0.6 1" size=".02" type="capsule"/>
		<geom conaffinity="1" contype="1" fromto="-.3 -.3 .01 -.3 .3 .01" name="sideW" rgba="0.9 0.4 0.6 1" size=".02" type="capsule"/>
		<!-- Arm -->
		<geom conaffinity="0" contype="0" fromto="0 0 0 0 0 0.02" name="root" rgba="0.9 0.4 0.6 1" size=".011" type="cylinder"/>
		<body name="body0" pos="0 0 .01">
			<geom fromto="0 0 0 0.1 0 0" name="link0" rgba="0.0 0.4 0.6 1" size=".01" type="capsule"/>
			<joint axis="0 0 1" limited="false" name="joint0" pos="0 0 0" type="hinge"/>
			<body name="body1" pos="0.1 0 0">
				<joint axis="0 0 1" limited="true" name="joint1" pos="0 0 0" range="-2.5 2.5" type="hinge"/>
				<geom fromto="0 0 0 0.1 0 0" name="link1" rgba="0.0 0.4 0.6 1" size=".01" type="capsule"/>
				<body name="gripper1" pos="0.1 0 0">
                    <joint axis="0 0 1" limited="true" name="joint2" pos="0 0 0" range="-1.5 0.0" type="hinge"/>
                    <geom fromto="0 0 0 0.03 -0.03 0" name="g1" rgba="0.0 0.4 0.6 1" size=".01" type="capsule"/>
                    <body name="gripper11" pos="0.03 -0.03 0">
                        <geom fromto="0 0 0 0.03 0.02 0" name="g11" rgba="0.0 0.4 0.6 1" size=".01" type="capsule"/>
                    </body>
				</body>

                <body name="gripper2" pos="0.1 0 0">
                    <joint axis="0 0 1" limited="true" name="joint3" pos="0 0 0" range="-3.0 3.0" type="hinge"/>
                    <geom fromto="0 0 0 0.03 0.03 0" name="g2" rgba="0.0 0.4 0.6 1" size=".01" type="capsule"/>
                    <body name="gripper21" pos="0.03 0.03 0">
                        <geom fromto="0 0 0 0.03 -0.02 0" name="g21" rgba="0.0 0.4 0.6 1" size=".01" type="capsule"/>
                    </body>
				</body>
			</body>
		</body>

        <body name="cyliner" pos="0.0 0.1 0.01">
            <geom name="cyl_geom" rgba="0.0 0.4 0.6 1" size=".015 0.01" type="cylinder" contype="1"/>
            <joint axis="1 0 0" limited="false" name="cyl_joint1" pos="0 0 0" type="slide"/>
            <joint axis="0 1 0" limited="false" name="cyl_joint2" pos="0 0 0" type="slide"/>
        </body>

		<!-- Target -->
        <body name="target_cyl" pos="0.0 0.2 0.01">
            <site name="target" pos="0 0 0" rgba="0.9 0.2 0.2 0.1" size=".015 0.01" type="cylinder"/>
        </body>

	</worldbody>

    <equality>
        <joint name="joint_const" joint1="joint2" joint2="joint3" polycoef="0 -1 0 0 0"/>
    </equality>

	<actuator>
		<motor ctrllimited="true" ctrlrange="-1.0 1.0" gear="200.0" joint="joint0"/>
		<motor ctrllimited="true" ctrlrange="-1.0 1.0" gear="200.0" joint="joint1"/>
        <motor ctrllimited="true" ctrlrange="-1.0 1.0" gear="10.0" joint="joint2"/>
	</actuator>
</mujoco>